Workbook

Sheet Master_620
A1: Case_ID | B1: Configuration | C1: Configuration_family | D1: Reference_specimen | E1: FE_model_file | F1: LHS_sample | G1: fc_MPa | H1: ALR | I1: rho_bl | J1: rho_sh | K1: rho_l | L1: rho_t | M1: dbar_mm | N1: webspacing_mm | O1: dbar1_mm | P1: no_bars_bl | Q1: rho_l_computed | R1: P_N | S1: epc0M | T1: My_kNm | U1: V_CE_kN | V1: V_MCyE_kN | W1: V_CE_over_V_MCyE | X1: FEMA_classification | Y1: dbar2_mm | Z1: Vmax_pos_kN | AA1: Delta_max_pos_mm | AB1: Delta_at_Vmax_pos_mm | AC1: Delta_y_pos_mm | AD1: Delta_20loss_pos_mm | AE1: Delta_u_pos_mm | AF1: Ultimate_source_pos | AG1: Reached_20loss_pos | AH1: mu_pos | AI1: Vmax_neg_kN | AJ1: Delta_max_neg_mm | AK1: Delta_at_Vmax_neg_mm | AL1: Delta_y_neg_mm | AM1: Delta_20loss_neg_mm | AN1: Delta_u_neg_mm | AO1: Ultimate_source_neg | AP1: Reached_20loss_neg | AQ1: mu_neg | AR1: Vmax_abs_kN | AS1: Delta_u_abs_mm | AT1: mu_abs | AU1: Delta_u_lower_bound_mm | AV1: Delta_u_upper_bound_mm | AW1: mu_lower_bound | AX1: mu_upper_bound | AY1: ML range status (see the red box in the Metadata sheet for the ranges) | AZ1: ML Out_of_range inputs | BA1: ML_E_max | BB1: ML_E_ALR | BC1: ML_E_rho_t
A2: Base model_LHS01 | B2: Base model | C2: Reference | D2: WSH6 | E2: run_FEmodel_webconf.py | F2: 1 | G2: 22.11414 | H2: 28.832066 | I2: 1.57 | J2: 1.5 | K2: 0.54 | L2: 0.25 | M2: 8 | N2: 125 | Q2: 0.53616515 | R2: 1866510.3 | S2: -0.0052570151 | T2: 931.9314 | U2: 672.06023 | V2: 206.17951 | W2: 3.2595878 | X2: Flexure-dominated | Z2: 543.999 | AA2: 95.1634 | AB2: 37.8091 | AC2: 15.881388 | AD2: 46.317002 | AE2: 46.317002 | AF2: 20pct_loss | AG2: TRUE | AH2: 2.9164329 | AI2: 543.695 | AJ2: 91.3101 | AK2: 39.0974 | AL2: 15.612095 | AM2: 46.130177 | AN2: 46.130177 | AO2: 20pct_loss | AP2: TRUE | AQ2: 2.9547718 | AR2: 543.999 | AS2: 46.317002 | AT2: 2.9547718 | AU2: 34.5988 | AV2: 49.420241 | AW2: 2.2072145 | AX2: 3.1527415 | AY2: Within calibration ranges | AZ2: None | BA2: =IF(COUNT(BB2:BC2)=2,MAX(BB2:BC2),"Missing input") -> 0 | BB2: =IF(AND(ISNUMBER(H2),Metadata!$H$5>Metadata!$G$5),MAX(Metadata!$G$5-H2,0,H2-Metadata!$H$5)/(Metadata!$H$5-Metadata!$G$5),"Missing input") -> 0 | BC2: =IF(AND(ISNUMBER(L2),Metadata!$H$8>Metadata!$G$8),MAX(Metadata!$G$8-L2,0,L2-Metadata!$H$8)/(Metadata!$H$8-Metadata!$G$8),"Missing input") -> 0
A3: Base model_LHS02 | B3: Base model | C3: Reference | D3: WSH6 | E3: run_FEmodel_webconf.py | F3: 2 | G3: 39.289373 | H3: 11.435997 | I3: 1.57 | J3: 1.5 | K3: 0.54 | L3: 0.25 | M3: 8 | N3: 125 | Q3: 0.53616515 | R3: 1301660.8 | S3: -0.0032987621 | T3: 682.24592 | U3: 750.05746 | V3: 150.93936 | W3: 4.9692634 | X3: Flexure-dominated | Z3: 551.621 | AA3: 95.1634 | AB3: 51.2964 | AC3: 15.180845 | AE3: 95.1634 | AF3: delta_max_fallback | AG3: FALSE | AH3: 6.2686497 | AI3: 548.427 | AJ3: 91.3101 | AK3: 60.9428 | AL3: 14.7453 | AN3: 91.3101 | AO3: delta_max_fallback | AP3: FALSE | AQ3: 6.1924886 | AR3: 551.621 | AS3: 95.1634 | AT3: 6.2686497 | AU3: 71.08706 | AV3: 101.53935 | AW3: 4.6826813 | AX3: 6.6886493 | AY3: Within calibration ranges | AZ3: None | BA3: =IF(COUNT(BB3:BC3)=2,MAX(BB3:BC3),"Missing input") -> 0 | BB3: =IF(AND(ISNUMBER(H3),Metadata!$H$5>Metadata!$G$5),MAX(Metadata!$G$5-H3,0,H3-Metadata!$H$5)/(Metadata!$H$5-Metadata!$G$5),"Missing input") -> 0 | BC3: =IF(AND(ISNUMBER(L3),Metadata!$H$8>Metadata!$G$8),MAX(Metadata!$G$8-L3,0,L3-Metadata!$H$8)/(Metadata!$H$8-Metadata!$G$8),"Missing input") -> 0
A4: Base model_LHS03 | B4: Base model | C4: Reference | D4: WSH6 | E4: run_FEmodel_webconf.py | F4: 3 | G4: 50.720967 | H4: 41.572102 | I4: 1.57 | J4: 1.5 | K4: 0.54 | L4: 0.25 | M4: 8 | N4: 125 | Q4: 0.53616515 | R4: 6279453 | S4: -0.0055786534 | T4: 2795.5189 | U4: 792.59154 | V4: 618.47764 | W4: 1.2815201 | X4: Flexure-dominated | Z4: 1025.73 | AA4: 95.1634 | AB4: 29.7498 | AC4: 14.046562 | AD4: 31.362191 | AE4: 31.362191 | AF4: 20pct_loss | AG4: TRUE | AH4: 2.2327307 | AI4: 1028.78 | AJ4: 91.3101 | AK4: 30.3602 | AL4: 13.216089 | AM4: 32.170972 | AN4: 32.170972 | AO4: 20pct_loss | AP4: TRUE | AQ4: 2.4342277 | AR4: 1028.78 | AS4: 32.170972 | AT4: 2.4342277 | AU4: 24.031716 | AV4: 34.326427 | AW4: 1.8183681 | AX4: 2.597321 | AY4: Outside calibration ranges | AZ4: ALR | BA4: =IF(COUNT(BB4:BC4)=2,MAX(BB4:BC4),"Missing input") -> 0.046063612 | BB4: =IF(AND(ISNUMBER(H4),Metadata!$H$5>Metadata!$G$5),MAX(Metadata!$G$5-H4,0,H4-Metadata!$H$5)/(Metadata!$H$5-Metadata!$G$5),"Missing input") -> 0.046063612 | BC4: =IF(AND(ISNUMBER(L4),Metadata!$H$8>Metadata!$G$8),MAX(Metadata!$G$8-L4,0,L4-Metadata!$H$8)/(Metadata!$H$8-Metadata!$G$8),"Missing input") -> 0
A5: Base model_LHS04 | B5: Base model | C5: Reference | D5: WSH6 | E5: run_FEmodel_webconf.py | F5: 4 | G5: 40.065365 | H5: 25.230644 | I5: 1.57 | J5: 1.5 | K5: 0.54 | L5: 0.25 | M5: 8 | N5: 125 | Q5: 0.53616515 | R5: 2986346.2 | S5: -0.0049865957 | T5: 1323.2635 | U5: 753.12628 | V5: 292.75741 | W5: 2.5725268 | X5: Flexure-dominated | Z5: 769.551 | AA5: 95.1634 | AB5: 42.5196 | AC5: 15.237534 | AD5: 51.184497 | AE5: 51.184497 | AF5: 20pct_loss | AG5: TRUE | AH5: 3.3591063 | AI5: 765.362 | AJ5: 91.3101 | AK5: 39.3589 | AL5: 14.863861 | AM5: 51.291697 | AN5: 51.291697 | AO5: 20pct_loss | AP5: TRUE | AQ5: 3.4507654 | AR5: 769.551 | AS5: 51.291697 | AT5: 3.4507654 | AU5: 38.314897 | AV5: 54.72824 | AW5: 2.5777218 | AX5: 3.6819667 | AY5: Within calibration ranges | AZ5: None | BA5: =IF(COUNT(BB5:BC5)=2,MAX(BB5:BC5),"Missing input") -> 0 | BB5: =IF(AND(ISNUMBER(H5),Metadata!$H$5>Metadata!$G$5),MAX(Metadata!$G$5-H5,0,H5-Metadata!$H$5)/(Metadata!$H$5-Metadata!$G$5),"Missing input") -> 0 | BC5: =IF(AND(ISNUMBER(L5),Metadata!$H$8>Metadata!$G$8),MAX(Metadata!$G$8-L5,0,L5-Metadata!$H$8)/(Metadata!$H$8-Metadata!$G$8),"Missing input") -> 0
A6: Base model_LHS05 | B6: Base model | C6: Reference | D6: WSH6 | E6: run_FEmodel_webconf.py | F6: 5 | G6: 44.69165 | H6: 35.27886 | I6: 1.57 | J6: 1.5 | K6: 0.54 | L6: 0.25 | M6: 8 | N6: 125 | Q6: 0.53616515 | R6: 4683732.7 | S6: -0.0055329742 | T6: 2061.9786 | U6: 770.8356 | V6: 456.18996 | W6: 1.6897251 | X6: Flexure-dominated | Z6: 911.832 | AA6: 95.1634 | AB6: 34.0313 | AC6: 14.515034 | AD6: 37.423961 | AE6: 37.423961 | AF6: 20pct_loss | AG6: TRUE | AH6: 2.5782896 | AI6: 906.854 | AJ6: 91.3101 | AK6: 33.604 | AL6: 13.803331 | AM6: 36.859673 | AN6: 36.859673 | AO6: 20pct_loss | AP6: TRUE | AQ6: 2.6703463 | AR6: 911.832 | AS6: 37.423961 | AT6: 2.6703463 | AU6: 27.955699 | AV6: 39.931367 | AW6: 1.9947487 | AX6: 2.8492595 | AY6: Within calibration ranges | AZ6: None | BA6: =IF(COUNT(BB6:BC6)=2,MAX(BB6:BC6),"Missing input") -> 0 | BB6: =IF(AND(ISNUMBER(H6),Metadata!$H$5>Metadata!$G$5),MAX(Metadata!$G$5-H6,0,H6-Metadata!$H$5)/(Metadata!$H$5-Metadata!$G$5),"Missing input") -> 0 | BC6: =IF(AND(ISNUMBER(L6),Metadata!$H$8>Metadata!$G$8),MAX(Metadata!$G$8-L6,0,L6-Metadata!$H$8)/(Metadata!$H$8-Metadata!$G$8),"Missing input") -> 0
A7: Base model_LHS06 | B7: Base model | C7: Reference | D7: WSH6 | E7: run_FEmodel_webconf.py | F7: 6 | G7: 33.0865 | H7: 19.795806 | I7: 1.57 | J7: 1.5 | K7: 0.54 | L7: 0.25 | M7: 8 | N7: 125 | Q7: 0.53616515 | R7: 1918643.2 | S7: -0.0044211785 | T7: 915.03918 | U7: 724.3481 | V7: 202.4423 | W7: 3.5780472 | X7: Flexure-dominated | Z7: 616.862 | AA7: 95.1562 | AB7: 49.5823 | AC7: 15.366174 | AD7: 62.966901 | AE7: 62.966901 | AF7: 20pct_loss | AG7: TRUE | AH7: 4.0977606 | AI7: 615.079 | AJ7: 91.3172 | AK7: 39.3589 | AL7: 15.037701 | AM7: 58.63334 | AN7: 58.63334 | AO7: 20pct_loss | AP7: TRUE | AQ7: 3.8990894 | AR7: 616.862 | AS7: 62.966901 | AT7: 4.0977606 | AU7: 47.036275 | AV7: 67.185683 | AW7: 3.0610272 | AX7: 4.3723106 | AY7: Within calibration ranges | AZ7: None | BA7: =IF(COUNT(BB7:BC7)=2,MAX(BB7:BC7),"Missing input") -> 0 | BB7: =IF(AND(ISNUMBER(H7),Metadata!$H$5>Metadata!$G$5),MAX(Metadata!$G$5-H7,0,H7-Metadata!$H$5)/(Metadata!$H$5-Metadata!$G$5),"Missing input") -> 0 | BC7: =IF(AND(ISNUMBER(L7),Metadata!$H$8>Metadata!$G$8),MAX(Metadata!$G$8-L7,0,L7-Metadata!$H$8)/(Metadata!$H$8-Metadata!$G$8),"Missing input") -> 0
A8: Base model_LHS07 | B8: Base model | C8: Reference | D8: WSH6 | E8: run_FEmodel_webconf.py | F8: 7 | G8: 42.943728 | H8: 31.604416 | I8: 1.57 | J8: 1.5 | K8: 0.54 | L8: 0.25 | M8: 8 | N8: 125 | Q8: 0.53616515 | R8: 4025355.6 | S8: -0.0054071197 | T8: 1767.1252 | U8: 764.25752 | V8: 390.9569 | W8: 1.9548383 | X8: Flexure-dominated | Z8: 866.175 | AA8: 95.1634 | AB8: 37.0536 | AC8: 14.901202 | AD8: 41.157465 | AE8: 41.157465 | AF8: 20pct_loss | AG8: TRUE | AH8: 2.7620232 | AI8: 862.743 | AJ8: 91.3101 | AK8: 36.7431 | AL8: 14.350079 | AM8: 39.961967 | AN8: 39.961967 | AO8: 20pct_loss | AP8: TRUE | AQ8: 2.7847907 | AR8: 866.175 | AS8: 41.157465 | AT8: 2.7847907 | AU8: 30.744626 | AV8: 43.915015 | AW8: 2.0802386 | AX8: 2.9713716 | AY8: Within calibration ranges | AZ8: None | BA8: =IF(COUNT(BB8:BC8)=2,MAX(BB8:BC8),"Missing input") -> 0 | BB8: =IF(AND(ISNUMBER(H8),Metadata!$H$5>Metadata!$G$5),MAX(Metadata!$G$5-H8,0,H8-Metadata!$H$5)/(Metadata!$H$5-Metadata!$G$5),"Missing input") -> 0 | BC8: =IF(AND(ISNUMBER(L8),Metadata!$H$8>Metadata!$G$8),MAX(Metadata!$G$8-L8,0,L8-Metadata!$H$8)/(Metadata!$H$8-Metadata!$G$8),"Missing input") -> 0
A9: Base model_LHS08 | B9: Base model | C9: Reference | D9: WSH6 | E9: run_FEmodel_webconf.py | F9: 8 | G9: 29.155455 | H9: 7.3398505 | I9: 1.57 | J9: 1.5 | K9: 0.54 | L9: 0.25 | M9: 8 | N9: 125 | Q9: 0.53616515 | R9: 595711.37 | S9: -0.0027297983 | T9: 480.50832 | U9: 706.7859 | V9: 106.30715 | W9: 6.6485265 | X9: Flexure-dominated | Z9: 414.678 | AA9: 95.1634 | AB9: 65.0062 | AC9: 16.034242 | AE9: 95.1634 | AF9: delta_max_fallback | AG9: FALSE | AH9: 5.935011 | AI9: 411.174 | AJ9: 91.3101 | AK9: 64.8115 | AL9: 15.465795 | AN9: 91.3101 | AO9: delta_max_fallback | AP9: FALSE | AQ9: 5.9040032 | AR9: 414.678 | AS9: 95.1634 | AT9: 5.935011 | AU9: 71.08706 | AV9: 101.53935 | AW9: 4.4334532 | AX9: 6.3326567 | AY9: Within calibration ranges | AZ9: None | BA9: =IF(COUNT(BB9:BC9)=2,MAX(BB9:BC9),"Missing input") -> 0 | BB9: =IF(AND(ISNUMBER(H9),Metadata!$H$5>Metadata!$G$5),MAX(Metadata!$G$5-H9,0,H9-Metadata!$H$5)/(Metadata!$H$5-Metadata!$G$5),"Missing input") -> 0 | BC9: =IF(AND(ISNUMBER(L9),Metadata!$H$8>Metadata!$G$8),MAX(Metadata!$G$8-L9,0,L9-Metadata!$H$8)/(Metadata!$H$8-Metadata!$G$8),"Missing input") -> 0
A10: Base model_LHS09 | B10: Base model | C10: Reference | D10: WSH6 | E10: run_FEmodel_webconf.py | F10: 9 | G10: 59.748609 | H10: 37.783512 | I10: 1.57 | J10: 1.5 | K10: 0.54 | L10: 0.25 | M10: 8 | N10: 125 | Q10: 0.53616515 | R10: 6726258.3 | S10: -0.0055750733 | T10: 2958.9793 | U10: 822.87545 | V10: 654.64145 | W10: 1.2569865 | X10: Flexure-dominated | Z10: 1157.19 | AA10: 95.1634 | AB10: 32.5202 | AC10: 14.692825 | AD10: 34.622735 | AE10: 34.622735 | AF10: 20pct_loss | AG10: TRUE | AH10: 2.3564382 | AI10: 1156.84 | AJ10: 91.3101 | AK10: 32.2893 | AL10: 13.92541 | AM10: 33.94974 | AN10: 33.94974 | AO10: 20pct_loss | AP10: TRUE | AQ10: 2.4379706 | AR10: 1157.19 | AS10: 34.622735 | AT10: 2.4379706 | AU10: 25.863183 | AV10: 36.942458 | AW10: 1.821164 | AX10: 2.6013146 | AY10: Within calibration ranges | AZ10: None | BA10: =IF(COUNT(BB10:BC10)=2,MAX(BB10:BC10),"Missing input") -> 0 | BB10: =IF(AND(ISNUMBER(H10),Metadata!$H$5>Metadata!$G$5),MAX(Metadata!$G$5-H10,0,H10-Metadata!$H$5)/(Metadata!$H$5-Metadata!$G$5),"Missing input") -> 0 | BC10: =IF(AND(ISNUMBER(L10),Metadata!$H$8>Metadata!$G$8),MAX(Metadata!$G$8-L10,0,L10-Metadata!$H$8)/(Metadata!$H$8-Metadata!$G$8),"Missing input") -> 0
A11: Base model_LHS10 | B11: Base model | C11: Reference | D11: WSH6 | E11: run_FEmodel_webconf.py | F11: 10 | G11: 34.746338 | H11: 23.741461 | I11: 1.57 | J11: 1.5 | K11: 0.54 | L11: 0.25 | M11: 8 | N11: 125 | Q11: 0.53616515 | R11: 2428507.8 | S11: -0.0048497307 | T11: 1111.2173 | U11: 731.44834 | V11: 245.84454 | W11: 2.9752474 | X11: Flexure-dominated | Z11: 685.071 | AA11: 95.1634 | AB11: 44.0137 | AC11: 15.47756 | AD11: 54.194583 | AE11: 54.194583 | AF11: 20pct_loss | AG11: TRUE | AH11: 3.5014939 | AI11: 679.572 | AJ11: 91.3101 | AK11: 39.3589 | AL11: 15.018495 | AM11: 53.263618 | AN11: 53.263618 | AO11: 20pct_loss | AP11: TRUE | AQ11: 3.546535 | AR11: 685.071 | AS11: 54.194583 | AT11: 3.546535 | AU11: 40.483354 | AV11: 57.82562 | AW11: 2.6492616 | AX11: 3.7841528 | AY11: Within calibration ranges | AZ11: None | BA11: =IF(COUNT(BB11:BC11)=2,MAX(BB11:BC11),"Missing input") -> 0 | BB11: =IF(AND(ISNUMBER(H11),Metadata!$H$5>Metadata!$G$5),MAX(Metadata!$G$5-H11,0,H11-Metadata!$H$5)/(Metadata!$H$5-Metadata!$G$5),"Missing input") -> 0 | BC11: =IF(AND(ISNUMBER(L11),Metadata!$H$8>Metadata!$G$8),MAX(Metadata!$G$8-L11,0,L11-Metadata!$H$8)/(Metadata!$H$8-Metadata!$G$8),"Missing input") -> 0
A12: Base model_LHS11 | B12: Base model | C12: Reference | D12: WSH6 | E12: run_FEmodel_webconf.py | F12: 11 | G12: 24.502162 | H12: 33.048591 | I12: 1.57 | J12: 1.5 | K12: 0.54 | L12: 0.25 | M12: 8 | N12: 125 | Q12: 0.53616515 | R12: 2383007.1 | S12: -0.0054661474 | T12: 1134.972 | U12: 684.38581 | V12: 251.1 | W12: 2.7255508 | X12: Flexure-dominated | Z12: 594.906 | AA12: 95.1634 | AB12: 36.0462 | AC12: 15.223573 | AD12: 40.609287 | AE12: 40.609287 | AF12: 20pct_loss | AG12: TRUE | AH12: 2.6675266 | AI12: 590.427 | AJ12: 91.3101 | AK12: 35.6967 | AL12: 14.583646 | AM12: 39.912115 | AN12: 39.912115 | AO12: 20pct_loss | AP12: TRUE | AQ12: 2.7367721 | AR12: 594.906 | AS12: 40.609287 | AT12: 2.7367721 | AU12: 30.335138 | AV12: 43.33011 | AW12: 2.0443687 | AX12: 2.9201358 | AY12: Within calibration ranges | AZ12: None | BA12: =IF(COUNT(BB12:BC12)=2,MAX(BB12:BC12),"Missing input") -> 0 | BB12: =IF(AND(ISNUMBER(H12),Metadata!$H$5>Metadata!$G$5),MAX(Metadata!$G$5-H12,0,H12-Metadata!$H$5)/(Metadata!$H$5-Metadata!$G$5),"Missing input") -> 0 | BC12: =IF(AND(ISNUMBER(L12),Metadata!$H$8>Metadata!$G$8),MAX(Metadata!$G$8-L12,0,L12-Metadata!$H$8)/(Metadata!$H$8-Metadata!$G$8),"Missing input") -> 0
A13: Base model_LHS12 | B13: Base model | C13: Reference | D13: WSH6 | E13: run_FEmodel_webconf.py | F13: 12 | G13: 56.241154 | H13: 14.787645 | I13: 1.57 | J13: 1.5 | K13: 0.54 | L13: 0.25 | M13: 8 | N13: 125 | Q13: 0.53616515 | R13: 2448743.9 | S13: -0.0037693155 | T13: 1060.8343 | U13: 811.40112 | V13: 234.69786 | W13: 3.4572157 | X13: Flexure-dominated | Z13: 770.38 | AA13: 95.1634 | AB13: 51.2964 | AC13: 14.575598 | AD13: 82.815587 | AE13: 82.815587 | AF13: 20pct_loss | AG13: TRUE | AH13: 5.6817969 | AI13: 765.955 | AJ13: 91.3101 | AK13: 51.7576 | AL13: 14.188555 | AM13: 81.947691 | AN13: 81.947691 | AO13: 20pct_loss | AP13: TRUE | AQ13: 5.7756192 | AR13: 770.38 | AS13: 82.815587 | AT13: 5.7756192 | AU13: 61.863243 | AV13: 88.364231 | AW13: 4.3143875 | AX13: 6.1625856 | AY13: Within calibration ranges | AZ13: None | BA13: =IF(COUNT(BB13:BC13)=2,MAX(BB13:BC13),"Missing input") -> 0 | BB13: =IF(AND(ISNUMBER(H13),Metadata!$H$5>Metadata!$G$5),MAX(Metadata!$G$5-H13,0,H13-Metadata!$H$5)/(Metadata!$H$5-Metadata!$G$5),"Missing input") -> 0 | BC13: =IF(AND(ISNUMBER(L13),Metadata!$H$8>Metadata!$G$8),MAX(Metadata!$G$8-L13,0,L13-Metadata!$H$8)/(Metadata!$H$8-Metadata!$G$8),"Missing input") -> 0
A14: Base model_LHS13 | B14: Base model | C14: Reference | D14: WSH6 | E14: run_FEmodel_webconf.py | F14: 13 | G14: 49.119901 | H14: 22.549335 | I14: 1.57 | J14: 1.5 | K14: 0.54 | L14: 0.25 | M14: 8 | N14: 125 | Q14: 0.53616515 | R14: 3276584.6 | S14: -0.0047299668 | T14: 1412.9688 | U14: 786.94653 | V14: 312.60372 | W14: 2.5173934 | X14: Flexure-dominated | Z14: 852.654 | AA14: 95.1634 | AB14: 44.9102 | AC14: 15.152109 | AD14: 57.026724 | AE14: 57.026724 | AF14: 20pct_loss | AG14: TRUE | AH14: 3.7636163 | AI14: 847.754 | AJ14: 91.3101 | AK14: 45.5743 | AL14: 14.830516 | AM14: 56.856433 | AN14: 56.856433 | AO14: 20pct_loss | AP14: TRUE | AQ14: 3.8337461 | AR14: 852.654 | AS14: 57.026724 | AT14: 3.8337461 | AU14: 42.598963 | AV14: 60.847515 | AW14: 2.8638083 | AX14: 4.090607 | AY14: Within calibration ranges | AZ14: None | BA14: =IF(COUNT(BB14:BC14)=2,MAX(BB14:BC14),"Missing input") -> 0 | BB14: =IF(AND(ISNUMBER(H14),Metadata!$H$5>Metadata!$G$5),MAX(Metadata!$G$5-H14,0,H14-Metadata!$H$5)/(Metadata!$H$5-Metadata!$G$5),"Missing input") -> 0 | BC14: =IF(AND(ISNUMBER(L14),Metadata!$H$8>Metadata!$G$8),MAX(Metadata!$G$8-L14,0,L14-Metadata!$H$8)/(Metadata!$H$8-Metadata!$G$8),"Missing input") -> 0
A15: Base model_LHS14 | B15: Base model | C15: Reference | D15: WSH6 | E15: run_FEmodel_webconf.py | F15: 14 | G15: 37.958866 | H15: 9.8264864 | I15: 1.57 | J15: 1.5 | K15: 0.54 | L15: 0.25 | M15: 8 | N15: 125 | Q15: 0.53616515 | R15: 1072728.2 | S15: -0.0030721352 | T15: 610.81355 | U15: 744.7243 | V15: 135.13574 | W15: 5.5109351 | X15: Flexure-dominated | Z15: 512.55 | AA15: 95.1648 | AB15: 63.7122 | AC15: 15.375727 | AE15: 95.1648 | AF15: delta_max_fallback | AG15: FALSE | AH15: 6.1892878 | AI15: 509.516 | AJ15: 91.3087 | AK15: 63.5219 | AL15: 14.947768 | AM15: 78.520592 | AN15: 78.520592 | AO15: 20pct_loss | AP15: TRUE | AQ15: 5.2529977 | AR15: 512.55 | AS15: 95.1648 | AT15: 6.1892878 | AU15: 71.088106 | AV15: 101.54084 | AW15: 4.623398 | AX15: 6.6039701 | AY15: Within calibration ranges | AZ15: None | BA15: =IF(COUNT(BB15:BC15)=2,MAX(BB15:BC15),"Missing input") -> 0 | BB15: =IF(AND(ISNUMBER(H15),Metadata!$H$5>Metadata!$G$5),MAX(Metadata!$G$5-H15,0,H15-Metadata!$H$5)/(Metadata!$H$5-Metadata!$G$5),"Missing input") -> 0 | BC15: =IF(AND(ISNUMBER(L15),Metadata!$H$8>Metadata!$G$8),MAX(Metadata!$G$8-L15,0,L15-Metadata!$H$8)/(Metadata!$H$8-Metadata!$G$8),"Missing input") -> 0
A16: Base model_LHS15 | B16: Base model | C16: Reference | D16: WSH6 | E16: run_FEmodel_webconf.py | F16: 15 | G16: 27.308053 | H16: 5.2772179 | I16: 1.57 | J16: 1.5 | K16: 0.54 | L16: 0.25 | M16: 8 | N16: 125 | Q16: 0.53616515 | R16: 386052.96 | S16: -0.0024589482 | T16: 428.52672 | U16: 698.12364 | V16: 94.806797 | W16: 7.3636455 | X16: Flexure-dominated | Z16: 372.884 | AA16: 95.1331 | AB16: 51.2964 | AC16: 16.373133 | AE16: 95.1331 | AF16: delta_max_fallback | AG16: FALSE | AH16: 5.8103175 | AI16: 371.561 | AJ16: 91.3403 | AK16: 32.2893 | AL16: 15.939289 | AM16: 77.695292 | AN16: 77.695292 | AO16: 20pct_loss | AP16: TRUE | AQ16: 4.8744516 | AR16: 372.884 | AS16: 95.1331 | AT16: 5.8103175 | AU16: 71.064426 | AV16: 101.50702 | AW16: 4.3403072 | AX16: 6.1996088 | AY16: Within calibration ranges | AZ16: None | BA16: =IF(COUNT(BB16:BC16)=2,MAX(BB16:BC16),"Missing input") -> 0 | BB16: =IF(AND(ISNUMBER(H16),Metadata!$H$5>Metadata!$G$5),MAX(Metadata!$G$5-H16,0,H16-Metadata!$H$5)/(Metadata!$H$5-Metadata!$G$5),"Missing input") -> 0 | BC16: =IF(AND(ISNUMBER(L16),Metadata!$H$8>Metadata!$G$8),MAX(Metadata!$G$8-L16,0,L16-Metadata!$H$8)/(Metadata!$H$8-Metadata!$G$8),"Missing input") -> 0
A17: Base model_LHS16 | B17: Base model | C17: Reference | D17: WSH6 | E17: run_FEmodel_webconf.py | F17: 16 | G17: 31.125212 | H17: 39.506907 | I17: 1.57 | J17: 1.5 | K17: 0.54 | L17: 0.25 | M17: 8 | N17: 125 | Q17: 0.53616515 | R17: 3642703.9 | S17: -0.0055852406 | T17: 1657.5347 | U17: 715.72466 | V17: 366.71121 | W17: 1.9517392 | X17: Flexure-dominated | Z17: 710.031 | AA17: 95.1634 | AB17: 31.2609 | AC17: 13.989533 | AD17: 34.21212 | AE17: 34.21212 | AF17: 20pct_loss | AG17: TRUE | AH17: 2.4455513 | AI17: 715.681 | AJ17: 91.3101 | AK17: 32.0749 | AL17: 13.567638 | AM17: 33.496748 | AN17: 33.496748 | AO17: 20pct_loss | AP17: TRUE | AQ17: 2.468871 | AR17: 715.681 | AS17: 34.21212 | AT17: 2.468871 | AU17: 25.556454 | AV17: 36.504332 | AW17: 1.8442467 | AX17: 2.6342854 | AY17: Within calibration ranges | AZ17: None | BA17: =IF(COUNT(BB17:BC17)=2,MAX(BB17:BC17),"Missing input") -> 0 | BB17: =IF(AND(ISNUMBER(H17),Metadata!$H$5>Metadata!$G$5),MAX(Metadata!$G$5-H17,0,H17-Metadata!$H$5)/(Metadata!$H$5-Metadata!$G$5),"Missing input") -> 0 | BC17: =IF(AND(ISNUMBER(L17),Metadata!$H$8>Metadata!$G$8),MAX(Metadata!$G$8-L17,0,L17-Metadata!$H$8)/(Metadata!$H$8-Metadata!$G$8),"Missing input") -> 0
A18: Base model_LHS17 | B18: Base model | C18: Reference | D18: WSH6 | E18: run_FEmodel_webconf.py | F18: 17 | G18: 46.390186 | H18: 16.213875 | I18: 1.57 | J18: 1.5 | K18: 0.54 | L18: 0.25 | M18: 8 | N18: 125 | Q18: 0.53616515 | R18: 2210215.4 | S18: -0.0039638908 | T18: 992.19235 | U18: 777.10568 | V18: 219.51158 | W18: 3.540158 | X18: Flexure-dominated | Z18: 708.903 | AA18: 95.1634 | AB18: 51.2964 | AC18: 14.955036 | AD18: 77.933542 | AE18: 77.933542 | AF18: 20pct_loss | AG18: TRUE | AH18: 5.2111905 | AI18: 704.425 | AJ18: 91.3101 | AK18: 51.7576 | AL18: 14.520759 | AM18: 78.463475 | AN18: 78.463475 | AO18: 20pct_loss | AP18: TRUE | AQ18: 5.4035382 | AR18: 708.903 | AS18: 78.463475 | AT18: 5.4035382 | AU18: 58.612216 | AV18: 83.720528 | AW18: 4.036443 | AX18: 5.7655753 | AY18: Within calibration ranges | AZ18: None | BA18: =IF(COUNT(BB18:BC18)=2,MAX(BB18:BC18),"Missing input") -> 0 | BB18: =IF(AND(ISNUMBER(H18),Metadata!$H$5>Metadata!$G$5),MAX(Metadata!$G$5-H18,0,H18-Metadata!$H$5)/(Metadata!$H$5-Metadata!$G$5),"Missing input") -> 0 | BC18: =IF(AND(ISNUMBER(L18),Metadata!$H$8>Metadata!$G$8),MAX(Metadata!$G$8-L18,0,L18-Metadata!$H$8)/(Metadata!$H$8-Metadata!$G$8),"Missing input") -> 0
A19: Base model_LHS18 | B19: Base model | C19: Reference | D19: WSH6 | E19: run_FEmodel_webconf.py | F19: 18 | G19: 54.165408 | H19: 18.252758 | I19: 1.57 | J19: 1.5 | K19: 0.54 | L19: 0.25 | M19: 8 | N19: 125 | Q19: 0.53616515 | R19: 2919725.6 | S19: -0.0042307787 | T19: 1250.2446 | U19: 804.4414 | V19: 276.60279 | W19: 2.9082909 | X19: Flexure-dominated | Z19: 832.379 | AA19: 95.1634 | AB19: 51.2964 | AC19: 14.884526 | AD19: 70.353318 | AE19: 70.353318 | AF19: 20pct_loss | AG19: TRUE | AH19: 4.7266077 | AI19: 828.08 | AJ19: 91.3101 | AK19: 51.414 | AL19: 14.603005 | AM19: 70.353655 | AN19: 70.353655 | AO19: 20pct_loss | AP19: TRUE | AQ19: 4.8177518 | AR19: 832.379 | AS19: 70.353655 | AT19: 4.8177518 | AU19: 52.55418 | AV19: 75.06735 | AW19: 3.5988606 | AX19: 5.1405412 | AY19: Within calibration ranges | AZ19: None | BA19: =IF(COUNT(BB19:BC19)=2,MAX(BB19:BC19),"Missing input") -> 0 | BB19: =IF(AND(ISNUMBER(H19),Metadata!$H$5>Metadata!$G$5),MAX(Metadata!$G$5-H19,0,H19-Metadata!$H$5)/(Metadata!$H$5-Metadata!$G$5),"Missing input") -> 0 | BC19: =IF(AND(ISNUMBER(L19),Metadata!$H$8>Metadata!$G$8),MAX(Metadata!$G$8-L19,0,L19-Metadata!$H$8)/(Metadata!$H$8-Metadata!$G$8),"Missing input") -> 0
A20: Base model_LHS19 | B20: Base model | C20: Reference | D20: WSH6 | E20: run_FEmodel_webconf.py | F20: 19 | G20: 21.707483 | H20: 43.497365 | I20: 1.57 | J20: 1.5 | K20: 0.54 | L20: 0.25 | M20: 8 | N20: 125 | Q20: 0.53616515 | R20: 2786376.3 | S20: -0.0055552281 | T20: 1327.8442 | U20: 669.8961 | V20: 293.77084 | W20: 2.2803356 | X20: Flexure-dominated | Z20: 562.459 | AA20: 95.1634 | AB20: 29.498 | AC20: 13.845727 | AD20: 32.582868 | AE20: 32.582868 | AF20: 20pct_loss | AG20: TRUE | AH20: 2.3532796 | AI20: 568.924 | AJ20: 91.3101 | AK20: 30.5745 | AL20: 13.425343 | AM20: 32.294116 | AN20: 32.294116 | AO20: 20pct_loss | AP20: TRUE | AQ20: 2.4054592 | AR20: 568.924 | AS20: 32.582868 | AT20: 2.4054592 | AU20: 24.339402 | AV20: 34.76592 | AW20: 1.796878 | AX20: 2.5666249 | AY20: Outside calibration ranges | AZ20: ALR | BA20: =IF(COUNT(BB20:BC20)=2,MAX(BB20:BC20),"Missing input") -> 0.094596678 | BB20: =IF(AND(ISNUMBER(H20),Metadata!$H$5>Metadata!$G$5),MAX(Metadata!$G$5-H20,0,H20-Metadata!$H$5)/(Metadata!$H$5-Metadata!$G$5),"Missing input") -> 0.094596678 | BC20: =IF(AND(ISNUMBER(L20),Metadata!$H$8>Metadata!$G$8),MAX(Metadata!$G$8-L20,0,L20-Metadata!$H$8)/(Metadata!$H$8-Metadata!$G$8),"Missing input") -> 0
A21: Base model_LHS20 | B21: Base model | C21: Reference | D21: WSH6 | E21: run_FEmodel_webconf.py | F21: 20 | G21: 53.035991 | H21: 30.346543 | I21: 1.57 | J21: 1.5 | K21: 0.54 | L21: 0.25 | M21: 8 | N21: 125 | Q21: 0.53616515 | R21: 4782098.3 | S21: -0.0053451343 | T21: 2064.3921 | U21: 800.59853 | V21: 456.72392 | W21: 1.7529157 | X21: Flexure-dominated | Z21: 1003.94 | AA21: 95.1634 | AB21: 37.8091 | AC21: 15.069635 | AD21: 43.225377 | AE21: 43.225377 | AF21: 20pct_loss | AG21: TRUE | AH21: 2.8683759 | AI21: 1002.88 | AJ21: 91.3101 | AK21: 38.051 | AL21: 14.649799 | AM21: 41.575223 | AN21: 41.575223 | AO21: 20pct_loss | AP21: TRUE | AQ21: 2.8379381 | AR21: 1003.94 | AS21: 43.225377 | AT21: 2.8683759 | AU21: 32.289357 | AV21: 46.121478 | AW21: 2.1426768 | AX21: 3.0605571 | AY21: Within calibration ranges | AZ21: None | BA21: =IF(COUNT(BB21:BC21)=2,MAX(BB21:BC21),"Missing input") -> 0 | BB21: =IF(AND(ISNUMBER(H21),Metadata!$H$5>Metadata!$G$5),MAX(Metadata!$G$5-H21,0,H21-Metadata!$H$5)/(Metadata!$H$5-Metadata!$G$5),"Missing input") -> 0 | BC21: =IF(AND(ISNUMBER(L21),Metadata!$H$8>Metadata!$G$8),MAX(Metadata!$G$8-L21,0,L21-Metadata!$H$8)/(Metadata!$H$8-Metadata!$G$8),"Missing input") -> 0
A22: W-L_LHS01 | B22: W-L | C22: Web | D22: WSH6 | E22: run_FEmodel_webconf.py | F22: 1 | G22: 22.11414 | H22: 28.832066 | I22: 1.57 | J22: 1.5 | K22: 0.27 | L22: 0.18 | M22: 8 | N22: 250 | Q22: 0.26808257 | R22: 1866510.3 | S22: -0.0041993982 | T22: 931.9314 | U22: 549.48332 | V22: 206.17951 | W22: 2.6650724 | X22: Flexure-dominated | Z22: 509.855 | AA22: 95.1634 | AB22: 36.5499 | AC22: 13.666692 | AD22: 42.139915 | AE22: 42.139915 | AF22: 20pct_loss | AG22: TRUE | AH22: 3.0834027 | AI22: 507.417 | AJ22: 91.3101 | AK22: 35.9583 | AL22: 13.185077 | AM22: 40.049241 | AN22: 40.049241 | AO22: 20pct_loss | AP22: TRUE | AQ22: 3.0374673 | AR22: 509.855 | AS22: 42.139915 | AT22: 3.0834027 | AU22: 31.478516 | AV22: 44.963289 | AW22: 2.3033018 | AX22: 3.2899907 | AY22: Within calibration ranges | AZ22: None | BA22: =IF(COUNT(BB22:BC22)=2,MAX(BB22:BC22),"Missing input") -> 0 | BB22: =IF(AND(ISNUMBER(H22),Metadata!$H$5>Metadata!$G$5),MAX(Metadata!$G$5-H22,0,H22-Metadata!$H$5)/(Metadata!$H$5-Metadata!$G$5),"Missing input") -> 0 | BC22: =IF(AND(ISNUMBER(L22),Metadata!$H$8>Metadata!$G$8),MAX(Metadata!$G$8-L22,0,L22-Metadata!$H$8)/(Metadata!$H$8-Metadata!$G$8),"Missing input") -> 0
A23: W-L_LHS02 | B23: W-L | C23: Web | D23: WSH6 | E23: run_FEmodel_webconf.py | F23: 2 | G23: 39.289373 | H23: 11.435997 | I23: 1.57 | J23: 1.5 | K23: 0.27 | L23: 0.18 | M23: 8 | N23: 250 | Q23: 0.26808257 | R23: 1301660.8 | S23: -0.0028241322 | T23: 682.24592 | U23: 627.48055 | V23: 150.93936 | W23: 4.1571697 | X23: Flexure-dominated | Z23: 484.167 | AA23: 95.1634 | AB23: 62.4183 | AC23: 12.241724 | AE23: 95.1634 | AF23: delta_max_fallback | AG23: FALSE | AH23: 7.7736927 | AI23: 483.321 | AJ23: 91.3101 | AK23: 61.8025 | AL23: 11.772506 | AN23: 91.3101 | AO23: delta_max_fallback | AP23: FALSE | AQ23: 7.7562163 | AR23: 484.167 | AS23: 95.1634 | AT23: 7.7736927 | AU23: 71.08706 | AV23: 101.53935 | AW23: 5.8069484 | AX23: 8.2945301 | AY23: Within calibration ranges | AZ23: None | BA23: =IF(COUNT(BB23:BC23)=2,MAX(BB23:BC23),"Missing input") -> 0 | BB23: =IF(AND(ISNUMBER(H23),Metadata!$H$5>Metadata!$G$5),MAX(Metadata!$G$5-H23,0,H23-Metadata!$H$5)/(Metadata!$H$5-Metadata!$G$5),"Missing input") -> 0 | BC23: =IF(AND(ISNUMBER(L23),Metadata!$H$8>Metadata!$G$8),MAX(Metadata!$G$8-L23,0,L23-Metadata!$H$8)/(Metadata!$H$8-Metadata!$G$8),"Missing input") -> 0
A24: W-L_LHS03 | B24: W-L | C24: Web | D24: WSH6 | E24: run_FEmodel_webconf.py | F24: 3 | G24: 50.720967 | H24: 41.572102 | I24: 1.57 | J24: 1.5 | K24: 0.27 | L24: 0.18 | M24: 8 | N24: 250 | Q24: 0.26808257 | R24: 6279453 | S24: -0.0043224029 | T24: 2795.5189 | U24: 670.01463 | V24: 618.47764 | W24: 1.0833288 | X24: Shear-susceptible | Z24: 999.79 | AA24: 95.1634 | AB24: 25.7987 | AC24: 12.704555 | AD24: 26.034214 | AE24: 26.034214 | AF24: 20pct_loss | AG24: TRUE | AH24: 2.0492031 | AI24: 1005.74 | AJ24: 91.3101 | AK24: 26.2876 | AL24: 11.792141 | AM24: 26.982246 | AN24: 26.982246 | AO24: 20pct_loss | AP24: TRUE | AQ24: 2.288155 | AR24: 1005.74 | AS24: 26.982246 | AT24: 2.288155 | AU24: NA | AV24: NA | AW24: NA | AX24: NA | AY24: Outside calibration ranges | AZ24: ALR | BA24: =IF(COUNT(BB24:BC24)=2,MAX(BB24:BC24),"Missing input") -> 0.046063612 | BB24: =IF(AND(ISNUMBER(H24),Metadata!$H$5>Metadata!$G$5),MAX(Metadata!$G$5-H24,0,H24-Metadata!$H$5)/(Metadata!$H$5-Metadata!$G$5),"Missing input") -> 0.046063612 | BC24: =IF(AND(ISNUMBER(L24),Metadata!$H$8>Metadata!$G$8),MAX(Metadata!$G$8-L24,0,L24-Metadata!$H$8)/(Metadata!$H$8-Metadata!$G$8),"Missing input") -> 0
A25: W-L_LHS04 | B25: W-L | C25: Web | D25: WSH6 | E25: run_FEmodel_webconf.py | F25: 4 | G25: 40.065365 | H25: 25.230644 | I25: 1.57 | J25: 1.5 | K25: 0.27 | L25: 0.18 | M25: 8 | N25: 250 | Q25: 0.26808257 | R25: 2986346.2 | S25: -0.0040307655 | T25: 1323.2635 | U25: 630.54937 | V25: 292.75741 | W25: 2.1538289 | X25: Flexure-dominated | Z25: 726.929 | AA25: 95.0503 | AB25: 37.8091 | AC25: 13.156666 | AD25: 46.172164 | AE25: 46.172164 | AF25: 20pct_loss | AG25: TRUE | AH25: 3.5094122 | AI25: 726.83 | AJ25: 90.8177 | AK25: 39.0974 | AL25: 12.927323 | AM25: 39.830686 | AN25: 39.830686 | AO25: 20pct_loss | AP25: TRUE | AQ25: 3.081124 | AR25: 726.929 | AS25: 46.172164 | AT25: 3.5094122 | AU25: 34.490607 | AV25: 49.265699 | AW25: 2.6215309 | AX25: 3.7445428 | AY25: Within calibration ranges | AZ25: None | BA25: =IF(COUNT(BB25:BC25)=2,MAX(BB25:BC25),"Missing input") -> 0 | BB25: =IF(AND(ISNUMBER(H25),Metadata!$H$5>Metadata!$G$5),MAX(Metadata!$G$5-H25,0,H25-Metadata!$H$5)/(Metadata!$H$5-Metadata!$G$5),"Missing input") -> 0 | BC25: =IF(AND(ISNUMBER(L25),Metadata!$H$8>Metadata!$G$8),MAX(Metadata!$G$8-L25,0,L25-Metadata!$H$8)/(Metadata!$H$8-Metadata!$G$8),"Missing input") -> 0
A26: W-L_LHS05 | B26: W-L | C26: Web | D26: WSH6 | E26: run_FEmodel_webconf.py | F26: 5 | G26: 44.69165 | H26: 35.27886 | I26: 1.57 | J26: 1.5 | K26: 0.27 | L26: 0.18 | M26: 8 | N26: 250 | Q26: 0.26808257 | R26: 4683732.7 | S26: -0.0043434141 | T26: 2061.9786 | U26: 648.25869 | V26: 456.18996 | W26: 1.421028 | X26: Flexure-dominated | Z26: 885.397 | AA26: 95.1634 | AB26: 29.498 | AC26: 13.086103 | AD26: 31.084935 | AE26: 31.084935 | AF26: 20pct_loss | AG26: TRUE | AH26: 2.3754157 | AI26: 888.574 | AJ26: 91.3101 | AK26: 30.1458 | AL26: 12.561399 | AM26: 32.14356 | AN26: 32.14356 | AO26: 20pct_loss | AP26: TRUE | AQ26: 2.5589156 | AR26: 888.574 | AS26: 32.14356 | AT26: 2.5589156 | AU26: 24.011239 | AV26: 34.297178 | AW26: 1.91151 | AX26: 2.730363 | AY26: Within calibration ranges | AZ26: None | BA26: =IF(COUNT(BB26:BC26)=2,MAX(BB26:BC26),"Missing input") -> 0 | BB26: =IF(AND(ISNUMBER(H26),Metadata!$H$5>Metadata!$G$5),MAX(Metadata!$G$5-H26,0,H26-Metadata!$H$5)/(Metadata!$H$5-Metadata!$G$5),"Missing input") -> 0 | BC26: =IF(AND(ISNUMBER(L26),Metadata!$H$8>Metadata!$G$8),MAX(Metadata!$G$8-L26,0,L26-Metadata!$H$8)/(Metadata!$H$8-Metadata!$G$8),"Missing input") -> 0
A27: W-L_LHS06 | B27: W-L | C27: Web | D27: WSH6 | E27: run_FEmodel_webconf.py | F27: 6 | G27: 33.0865 | H27: 19.795806 | I27: 1.57 | J27: 1.5 | K27: 0.27 | L27: 0.18 | M27: 8 | N27: 250 | Q27: 0.26808257 | R27: 1918643.2 | S27: -0.0036480037 | T27: 915.03918 | U27: 601.77119 | V27: 202.4423 | W27: 2.9725566 | X27: Flexure-dominated | Z27: 568.487 | AA27: 95.1072 | AB27: 44.9102 | AC27: 12.966863 | AD27: 51.54605 | AE27: 51.54605 | AF27: 20pct_loss | AG27: TRUE | AH27: 3.9752135 | AI27: 565.763 | AJ27: 70.6177 | AK27: 39.3589 | AL27: 12.559725 | AM27: 51.893469 | AN27: 51.893469 | AO27: 20pct_loss | AP27: TRUE | AQ27: 4.131736 | AR27: 568.487 | AS27: 51.893469 | AT27: 4.131736 | AU27: 38.764421 | AV27: 55.370331 | AW27: 3.0864068 | AX27: 4.4085623 | AY27: Within calibration ranges | AZ27: None | BA27: =IF(COUNT(BB27:BC27)=2,MAX(BB27:BC27),"Missing input") -> 0 | BB27: =IF(AND(ISNUMBER(H27),Metadata!$H$5>Metadata!$G$5),MAX(Metadata!$G$5-H27,0,H27-Metadata!$H$5)/(Metadata!$H$5-Metadata!$G$5),"Missing input") -> 0 | BC27: =IF(AND(ISNUMBER(L27),Metadata!$H$8>Metadata!$G$8),MAX(Metadata!$G$8-L27,0,L27-Metadata!$H$8)/(Metadata!$H$8-Metadata!$G$8),"Missing input") -> 0
A28: W-L_LHS07 | B28: W-L | C28: Web | D28: WSH6 | E28: run_FEmodel_webconf.py | F28: 7 | G28: 42.943728 | H28: 31.604416 | I28: 1.57 | J28: 1.5 | K28: 0.27 | L28: 0.18 | M28: 8 | N28: 250 | Q28: 0.26808257 | R28: 4025355.6 | S28: -0.0042845926 | T28: 1767.1252 | U28: 641.68061 | V28: 390.9569 | W28: 1.6413078 | X28: Flexure-dominated | Z28: 835.905 | AA28: 95.1634 | AB28: 32.7721 | AC28: 13.301956 | AD28: 36.12219 | AE28: 36.12219 | AF28: 20pct_loss | AG28: TRUE | AH28: 2.7155547 | AI28: 834.643 | AJ28: 91.3101 | AK28: 32.2893 | AL28: 12.812615 | AM28: 35.771236 | AN28: 35.771236 | AO28: 20pct_loss | AP28: TRUE | AQ28: 2.7918764 | AR28: 835.905 | AS28: 36.12219 | AT28: 2.7918764 | AU28: 26.983276 | AV28: 38.542377 | AW28: 2.0855316 | AX28: 2.9789321 | AY28: Within calibration ranges | AZ28: None | BA28: =IF(COUNT(BB28:BC28)=2,MAX(BB28:BC28),"Missing input") -> 0 | BB28: =IF(AND(ISNUMBER(H28),Metadata!$H$5>Metadata!$G$5),MAX(Metadata!$G$5-H28,0,H28-Metadata!$H$5)/(Metadata!$H$5-Metadata!$G$5),"Missing input") -> 0 | BC28: =IF(AND(ISNUMBER(L28),Metadata!$H$8>Metadata!$G$8),MAX(Metadata!$G$8-L28,0,L28-Metadata!$H$8)/(Metadata!$H$8-Metadata!$G$8),"Missing input") -> 0
A29: W-L_LHS08 | B29: W-L | C29: Web | D29: WSH6 | E29: run_FEmodel_webconf.py | F29: 8 | G29: 29.155455 | H29: 7.3398505 | I29: 1.57 | J29: 1.5 | K29: 0.27 | L29: 0.18 | M29: 8 | N29: 250 | Q29: 0.26808257 | R29: 595711.37 | S29: -0.0023850338 | T29: 480.50832 | U29: 584.20899 | V29: 106.30715 | W29: 5.4954817 | X29: Flexure-dominated | Z29: 341.74 | AA29: 95.1634 | AB29: 74.7456 | AC29: 12.754423 | AE29: 95.1634 | AF29: delta_max_fallback | AG29: FALSE | AH29: 7.461208 | AI29: 341.574 | AJ29: 91.3101 | AK29: 73.7434 | AL29: 12.658306 | AN29: 91.3101 | AO29: delta_max_fallback | AP29: FALSE | AQ29: 7.2134536 | AR29: 341.74 | AS29: 95.1634 | AT29: 7.461208 | AU29: 71.08706 | AV29: 101.53935 | AW29: 5.5735224 | AX29: 7.9611089 | AY29: Within calibration ranges | AZ29: None | BA29: =IF(COUNT(BB29:BC29)=2,MAX(BB29:BC29),"Missing input") -> 0 | BB29: =IF(AND(ISNUMBER(H29),Metadata!$H$5>Metadata!$G$5),MAX(Metadata!$G$5-H29,0,H29-Metadata!$H$5)/(Metadata!$H$5-Metadata!$G$5),"Missing input") -> 0 | BC29: =IF(AND(ISNUMBER(L29),Metadata!$H$8>Metadata!$G$8),MAX(Metadata!$G$8-L29,0,L29-Metadata!$H$8)/(Metadata!$H$8-Metadata!$G$8),"Missing input") -> 0
A30: W-L_LHS09 | B30: W-L | C30: Web | D30: WSH6 | E30: run_FEmodel_webconf.py | F30: 9 | G30: 59.748609 | H30: 37.783512 | I30: 1.57 | J30: 1.5 | K30: 0.27 | L30: 0.18 | M30: 8 | N30: 250 | Q30: 0.26808257 | R30: 6726258.3 | S30: -0.0043519787 | T30: 2958.9793 | U30: 700.29854 | V30: 654.64145 | W30: 1.0697437 | X30: Shear-susceptible | Z30: 1130.99 | AA30: 95.1634 | AB30: 27.9868 | AC30: 13.481374 | AD30: 28.547638 | AE30: 28.547638 | AF30: 20pct_loss | AG30: TRUE | AH30: 2.1175614 | AI30: 1134.33 | AJ30: 91.3101 | AK30: 28.6454 | AL30: 12.758469 | AM30: 29.549725 | AN30: 29.549725 | AO30: 20pct_loss | AP30: TRUE | AQ30: 2.316087 | AR30: 1134.33 | AS30: 29.549725 | AT30: 2.316087 | AU30: NA | AV30: NA | AW30: NA | AX30: NA | AY30: Within calibration ranges | AZ30: None | BA30: =IF(COUNT(BB30:BC30)=2,MAX(BB30:BC30),"Missing input") -> 0 | BB30: =IF(AND(ISNUMBER(H30),Metadata!$H$5>Metadata!$G$5),MAX(Metadata!$G$5-H30,0,H30-Metadata!$H$5)/(Metadata!$H$5-Metadata!$G$5),"Missing input") -> 0 | BC30: =IF(AND(ISNUMBER(L30),Metadata!$H$8>Metadata!$G$8),MAX(Metadata!$G$8-L30,0,L30-Metadata!$H$8)/(Metadata!$H$8-Metadata!$G$8),"Missing input") -> 0
A31: W-L_LHS10 | B31: W-L | C31: Web | D31: WSH6 | E31: run_FEmodel_webconf.py | F31: 10 | G31: 34.746338 | H31: 23.741461 | I31: 1.57 | J31: 1.5 | K31: 0.27 | L31: 0.18 | M31: 8 | N31: 250 | Q31: 0.26808257 | R31: 2428507.8 | S31: -0.0039410675 | T31: 1111.2173 | U31: 608.87144 | V31: 245.84454 | W31: 2.4766522 | X31: Flexure-dominated | Z31: 638.136 | AA31: 95.1634 | AB31: 40.7266 | AC31: 13.095158 | AD31: 50.065211 | AE31: 50.065211 | AF31: 20pct_loss | AG31: TRUE | AH31: 3.8231849 | AI31: 637.891 | AJ31: 91.3101 | AK31: 39.3589 | AL31: 12.868038 | AM31: 49.828747 | AN31: 49.828747 | AO31: 20pct_loss | AP31: TRUE | AQ31: 3.872288 | AR31: 638.136 | AS31: 50.065211 | AT31: 3.872288 | AU31: 37.398713 | AV31: 53.41958 | AW31: 2.8925991 | AX31: 4.1317312 | AY31: Within calibration ranges | AZ31: None | BA31: =IF(COUNT(BB31:BC31)=2,MAX(BB31:BC31),"Missing input") -> 0 | BB31: =IF(AND(ISNUMBER(H31),Metadata!$H$5>Metadata!$G$5),MAX(Metadata!$G$5-H31,0,H31-Metadata!$H$5)/(Metadata!$H$5-Metadata!$G$5),"Missing input") -> 0 | BC31: =IF(AND(ISNUMBER(L31),Metadata!$H$8>Metadata!$G$8),MAX(Metadata!$G$8-L31,0,L31-Metadata!$H$8)/(Metadata!$H$8-Metadata!$G$8),"Missing input") -> 0
A32: W-L_LHS11 | B32: W-L | C32: Web | D32: WSH6 | E32: run_FEmodel_webconf.py | F32: 11 | G32: 24.502162 | H32: 33.048591 | I32: 1.57 | J32: 1.5 | K32: 0.27 | L32: 0.18 | M32: 8 | N32: 250 | Q32: 0.26808257 | R32: 2383007.1 | S32: -0.004314693 | T32: 1134.972 | U32: 561.80891 | V32: 251.1 | W32: 2.2373911 | X32: Flexure-dominated | Z32: 566.486 | AA32: 95.1634 | AB32: 32.0165 | AC32: 13.305208 | AD32: 35.924735 | AE32: 35.924735 | AF32: 20pct_loss | AG32: TRUE | AH32: 2.7000505 | AI32: 567.046 | AJ32: 91.3101 | AK32: 32.2893 | AL32: 12.835413 | AM32: 35.823811 | AN32: 35.823811 | AO32: 20pct_loss | AP32: TRUE | AQ32: 2.7910134 | AR32: 567.046 | AS32: 35.924735 | AT32: 2.7910134 | AU32: 26.835777 | AV32: 38.331692 | AW32: 2.084887 | AX32: 2.9780113 | AY32: Within calibration ranges | AZ32: None | BA32: =IF(COUNT(BB32:BC32)=2,MAX(BB32:BC32),"Missing input") -> 0 | BB32: =IF(AND(ISNUMBER(H32),Metadata!$H$5>Metadata!$G$5),MAX(Metadata!$G$5-H32,0,H32-Metadata!$H$5)/(Metadata!$H$5-Metadata!$G$5),"Missing input") -> 0 | BC32: =IF(AND(ISNUMBER(L32),Metadata!$H$8>Metadata!$G$8),MAX(Metadata!$G$8-L32,0,L32-Metadata!$H$8)/(Metadata!$H$8-Metadata!$G$8),"Missing input") -> 0
A33: W-L_LHS12 | B33: W-L | C33: Web | D33: WSH6 | E33: run_FEmodel_webconf.py | F33: 12 | G33: 56.241154 | H33: 14.787645 | I33: 1.57 | J33: 1.5 | K33: 0.27 | L33: 0.18 | M33: 8 | N33: 250 | Q33: 0.26808257 | R33: 2448743.9 | S33: -0.0031774352 | T33: 1060.8343 | U33: 688.82421 | V33: 234.69786 | W33: 2.9349404 | X33: Flexure-dominated | Z33: 707.721 | AA33: 94.8769 | AB33: 51.2964 | AC33: 12.18892 | AD33: 75.833752 | AE33: 75.833752 | AF33: 20pct_loss | AG33: TRUE | AH33: 6.2215319 | AI33: 706.506 | AJ33: 76.3341 | AK33: 51.7576 | AL33: 11.957883 | AM33: 64.853943 | AN33: 64.853943 | AO33: 20pct_loss | AP33: TRUE | AQ33: 5.4235305 | AR33: 707.721 | AS33: 75.833752 | AT33: 6.2215319 | AU33: 56.647813 | AV33: 80.914614 | AW33: 4.6474844 | AX33: 6.6383746 | AY33: Within calibration ranges | AZ33: None | BA33: =IF(COUNT(BB33:BC33)=2,MAX(BB33:BC33),"Missing input") -> 0 | BB33: =IF(AND(ISNUMBER(H33),Metadata!$H$5>Metadata!$G$5),MAX(Metadata!$G$5-H33,0,H33-Metadata!$H$5)/(Metadata!$H$5-Metadata!$G$5),"Missing input") -> 0 | BC33: =IF(AND(ISNUMBER(L33),Metadata!$H$8>Metadata!$G$8),MAX(Metadata!$G$8-L33,0,L33-Metadata!$H$8)/(Metadata!$H$8-Metadata!$G$8),"Missing input") -> 0
A34: W-L_LHS13 | B34: W-L | C34: Web | D34: WSH6 | E34: run_FEmodel_webconf.py | F34: 13 | G34: 49.119901 | H34: 22.549335 | I34: 1.57 | J34: 1.5 | K34: 0.27 | L34: 0.18 | M34: 8 | N34: 250 | Q34: 0.26808257 | R34: 3276584.6 | S34: -0.0038608405 | T34: 1412.9688 | U34: 664.36963 | V34: 312.60372 | W34: 2.1252774 | X34: Flexure-dominated | Z34: 803.847 | AA34: 95.1634 | AB34: 41.9219 | AC34: 13.041525 | AD34: 51.372679 | AE34: 51.372679 | AF34: 20pct_loss | AG34: TRUE | AH34: 3.9391618 | AI34: 801.81 | AJ34: 91.3101 | AK34: 39.3589 | AL34: 12.82383 | AM34: 51.508917 | AN34: 51.508917 | AO34: 20pct_loss | AP34: TRUE | AQ34: 4.0166562 | AR34: 803.847 | AS34: 51.508917 | AT34: 4.0166562 | AU34: 38.477161 | AV34: 54.960014 | AW34: 3.0004422 | AX34: 4.2857722 | AY34: Within calibration ranges | AZ34: None | BA34: =IF(COUNT(BB34:BC34)=2,MAX(BB34:BC34),"Missing input") -> 0 | BB34: =IF(AND(ISNUMBER(H34),Metadata!$H$5>Metadata!$G$5),MAX(Metadata!$G$5-H34,0,H34-Metadata!$H$5)/(Metadata!$H$5-Metadata!$G$5),"Missing input") -> 0 | BC34: =IF(AND(ISNUMBER(L34),Metadata!$H$8>Metadata!$G$8),MAX(Metadata!$G$8-L34,0,L34-Metadata!$H$8)/(Metadata!$H$8-Metadata!$G$8),"Missing input") -> 0
A35: W-L_LHS14 | B35: W-L | C35: Web | D35: WSH6 | E35: run_FEmodel_webconf.py | F35: 14 | G35: 37.958866 | H35: 9.8264864 | I35: 1.57 | J35: 1.5 | K35: 0.27 | L35: 0.18 | M35: 8 | N35: 250 | Q35: 0.26808257 | R35: 1072728.2 | S35: -0.0026506531 | T35: 610.81355 | U35: 622.14739 | V35: 135.13574 | W35: 4.6038701 | X35: Flexure-dominated | Z35: 436.247 | AA35: 95.0195 | AB35: 37.8091 | AC35: 11.969573 | AD35: 37.855573 | AE35: 37.855573 | AF35: 20pct_loss | AG35: TRUE | AH35: 3.1626501 | AI35: 435.011 | AJ35: 90.8485 | AK35: 32.2893 | AL35: 11.574958 | AN35: 90.8485 | AO35: delta_max_fallback | AP35: FALSE | AQ35: 7.8487109 | AR35: 436.247 | AS35: 90.8485 | AT35: 7.8487109 | AU35: 67.863829 | AV35: 96.93535 | AW35: 5.8629871 | AX35: 8.3745746 | AY35: Within calibration ranges | AZ35: None | BA35: =IF(COUNT(BB35:BC35)=2,MAX(BB35:BC35),"Missing input") -> 0 | BB35: =IF(AND(ISNUMBER(H35),Metadata!$H$5>Metadata!$G$5),MAX(Metadata!$G$5-H35,0,H35-Metadata!$H$5)/(Metadata!$H$5-Metadata!$G$5),"Missing input") -> 0 | BC35: =IF(AND(ISNUMBER(L35),Metadata!$H$8>Metadata!$G$8),MAX(Metadata!$G$8-L35,0,L35-Metadata!$H$8)/(Metadata!$H$8-Metadata!$G$8),"Missing input") -> 0
A36: W-L_LHS15 | B36: W-L | C36: Web | D36: WSH6 | E36: run_FEmodel_webconf.py | F36: 15 | G36: 27.308053 | H36: 5.2772179 | I36: 1.57 | J36: 1.5 | K36: 0.27 | L36: 0.18 | M36: 8 | N36: 250 | Q36: 0.26808257 | R36: 386052.96 | S36: -0.0021721759 | T36: 428.52672 | U36: 575.54673 | V36: 94.806797 | W36: 6.0707328 | X36: Flexure-dominated | Z36: 298.671 | AA36: 95.1634 | AB36: 77.8502 | AC36: 13.251328 | AE36: 95.1634 | AF36: delta_max_fallback | AG36: FALSE | AH36: 7.1814236 | AI36: 299.018 | AJ36: 91.3101 | AK36: 78.4318 | AL36: 13.107878 | AN36: 91.3101 | AO36: delta_max_fallback | AP36: FALSE | AQ36: 6.9660473 | AR36: 299.018 | AS36: 95.1634 | AT36: 7.1814236 | AU36: 71.08706 | AV36: 101.53935 | AW36: 5.3645234 | AX36: 7.6625789 | AY36: Within calibration ranges | AZ36: None | BA36: =IF(COUNT(BB36:BC36)=2,MAX(BB36:BC36),"Missing input") -> 0 | BB36: =IF(AND(ISNUMBER(H36),Metadata!$H$5>Metadata!$G$5),MAX(Metadata!$G$5-H36,0,H36-Metadata!$H$5)/(Metadata!$H$5-Metadata!$G$5),"Missing input") -> 0 | BC36: =IF(AND(ISNUMBER(L36),Metadata!$H$8>Metadata!$G$8),MAX(Metadata!$G$8-L36,0,L36-Metadata!$H$8)/(Metadata!$H$8-Metadata!$G$8),"Missing input") -> 0
A37: W-L_LHS16 | B37: W-L | C37: Web | D37: WSH6 | E37: run_FEmodel_webconf.py | F37: 16 | G37: 31.125212 | H37: 39.506907 | I37: 1.57 | J37: 1.5 | K37: 0.27 | L37: 0.18 | M37: 8 | N37: 250 | Q37: 0.26808257 | R37: 3642703.9 | S37: -0.0043445279 | T37: 1657.5347 | U37: 593.14775 | V37: 366.71121 | W37: 1.6174792 | X37: Flexure-dominated | Z37: 684.667 | AA37: 95.1634 | AB37: 26.7276 | AC37: 12.301209 | AD37: 28.341466 | AE37: 28.341466 | AF37: 20pct_loss | AG37: TRUE | AH37: 2.3039577 | AI37: 691.426 | AJ37: 91.3101 | AK37: 27.5737 | AL37: 11.791819 | AM37: 29.377596 | AN37: 29.377596 | AO37: 20pct_loss | AP37: TRUE | AQ37: 2.4913542 | AR37: 691.426 | AS37: 29.377596 | AT37: 2.4913542 | AU37: 21.945064 | AV37: 31.345895 | AW37: 1.8610416 | AX37: 2.6582749 | AY37: Within calibration ranges | AZ37: None | BA37: =IF(COUNT(BB37:BC37)=2,MAX(BB37:BC37),"Missing input") -> 0 | BB37: =IF(AND(ISNUMBER(H37),Metadata!$H$5>Metadata!$G$5),MAX(Metadata!$G$5-H37,0,H37-Metadata!$H$5)/(Metadata!$H$5-Metadata!$G$5),"Missing input") -> 0 | BC37: =IF(AND(ISNUMBER(L37),Metadata!$H$8>Metadata!$G$8),MAX(Metadata!$G$8-L37,0,L37-Metadata!$H$8)/(Metadata!$H$8-Metadata!$G$8),"Missing input") -> 0
A38: W-L_LHS17 | B38: W-L | C38: Web | D38: WSH6 | E38: run_FEmodel_webconf.py | F38: 17 | G38: 46.390186 | H38: 16.213875 | I38: 1.57 | J38: 1.5 | K38: 0.27 | L38: 0.18 | M38: 8 | N38: 250 | Q38: 0.26808257 | R38: 2210215.4 | S38: -0.0033204448 | T38: 992.19235 | U38: 654.52878 | V38: 219.51158 | W38: 2.9817505 | X38: Flexure-dominated | Z38: 648.916 | AA38: 95.1634 | AB38: 51.2964 | AC38: 12.432101 | AD38: 72.785655 | AE38: 72.785655 | AF38: 20pct_loss | AG38: TRUE | AH38: 5.8546544 | AI38: 647.533 | AJ38: 91.3101 | AK38: 51.7576 | AL38: 12.144708 | AM38: 72.817379 | AN38: 72.817379 | AO38: 20pct_loss | AP38: TRUE | AQ38: 5.9958113 | AR38: 648.916 | AS38: 72.817379 | AT38: 5.9958113 | AU38: 54.394582 | AV38: 77.696143 | AW38: 4.4788711 | AX38: 6.3975307 | AY38: Within calibration ranges | AZ38: None | BA38: =IF(COUNT(BB38:BC38)=2,MAX(BB38:BC38),"Missing input") -> 0 | BB38: =IF(AND(ISNUMBER(H38),Metadata!$H$5>Metadata!$G$5),MAX(Metadata!$G$5-H38,0,H38-Metadata!$H$5)/(Metadata!$H$5-Metadata!$G$5),"Missing input") -> 0 | BC38: =IF(AND(ISNUMBER(L38),Metadata!$H$8>Metadata!$G$8),MAX(Metadata!$G$8-L38,0,L38-Metadata!$H$8)/(Metadata!$H$8-Metadata!$G$8),"Missing input") -> 0
A39: W-L_LHS18 | B39: W-L | C39: Web | D39: WSH6 | E39: run_FEmodel_webconf.py | F39: 18 | G39: 54.165408 | H39: 18.252758 | I39: 1.57 | J39: 1.5 | K39: 0.27 | L39: 0.18 | M39: 8 | N39: 250 | Q39: 0.26808257 | R39: 2919725.6 | S39: -0.0035132056 | T39: 1250.2446 | U39: 681.8645 | V39: 276.60279 | W39: 2.4651396 | X39: Flexure-dominated | Z39: 774.875 | AA39: 95.1634 | AB39: 47.8824 | AC39: 12.59825 | AD39: 64.237766 | AE39: 64.237766 | AF39: 20pct_loss | AG39: TRUE | AH39: 5.0989434 | AI39: 773.165 | AJ39: 91.3101 | AK39: 47.9789 | AL39: 12.435475 | AM39: 64.04498 | AN39: 64.04498 | AO39: 20pct_loss | AP39: TRUE | AQ39: 5.1501835 | AR39: 774.875 | AS39: 64.237766 | AT39: 5.1501835 | AU39: 47.985611 | AV39: 68.541696 | AW39: 3.8471871 | AX39: 5.4952458 | AY39: Within calibration ranges | AZ39: None | BA39: =IF(COUNT(BB39:BC39)=2,MAX(BB39:BC39),"Missing input") -> 0 | BB39: =IF(AND(ISNUMBER(H39),Metadata!$H$5>Metadata!$G$5),MAX(Metadata!$G$5-H39,0,H39-Metadata!$H$5)/(Metadata!$H$5-Metadata!$G$5),"Missing input") -> 0 | BC39: =IF(AND(ISNUMBER(L39),Metadata!$H$8>Metadata!$G$8),MAX(Metadata!$G$8-L39,0,L39-Metadata!$H$8)/(Metadata!$H$8-Metadata!$G$8),"Missing input") -> 0
A40: W-L_LHS19 | B40: W-L | C40: Web | D40: WSH6 | E40: run_FEmodel_webconf.py | F40: 19 | G40: 21.707483 | H40: 43.497365 | I40: 1.57 | J40: 1.5 | K40: 0.27 | L40: 0.18 | M40: 8 | N40: 250 | Q40: 0.26808257 | R40: 2786376.3 | S40: -0.0042897021 | T40: 1327.8442 | U40: 547.31919 | V40: 293.77084 | W40: 1.8630821 | X40: Flexure-dominated | Z40: 545.442 | AA40: 81.7498 | AB40: 25.7987 | AC40: 12.370704 | AD40: 25.861095 | AE40: 25.861095 | AF40: 20pct_loss | AG40: TRUE | AH40: 2.0905111 | AI40: 546.695 | AJ40: 90.8598 | AK40: 26.2876 | AL40: 11.460515 | AM40: 27.901601 | AN40: 27.901601 | AO40: 20pct_loss | AP40: TRUE | AQ40: 2.4345853 | AR40: 546.695 | AS40: 27.901601 | AT40: 2.4345853 | AU40: 20.842496 | AV40: 29.771009 | AW40: 1.8186352 | AX40: 2.5977025 | AY40: Outside calibration ranges | AZ40: ALR | BA40: =IF(COUNT(BB40:BC40)=2,MAX(BB40:BC40),"Missing input") -> 0.094596678 | BB40: =IF(AND(ISNUMBER(H40),Metadata!$H$5>Metadata!$G$5),MAX(Metadata!$G$5-H40,0,H40-Metadata!$H$5)/(Metadata!$H$5-Metadata!$G$5),"Missing input") -> 0.094596678 | BC40: =IF(AND(ISNUMBER(L40),Metadata!$H$8>Metadata!$G$8),MAX(Metadata!$G$8-L40,0,L40-Metadata!$H$8)/(Metadata!$H$8-Metadata!$G$8),"Missing input") -> 0
...

Sheet Metadata
A1: Item | B1: Value
A2: Reference specimen | B2: WSH6
A3: Reference source | B3: Dazio, A., Beyer, K., & Bachmann, H. (2009). Quasi-static cyclic tests and plastic hinge analysis of RC structural walls. Engineering Structures, 31(7), 1556-1571.
A4: Reference properties | B4: wsh6_reference.py | F4: ML input | G4: Calibration min | H4: Calibration max
A5: Configuration source | B5: Configurations_model_input.xlsx | F5: ALR (%) | G5: 0.0757 | H5: 39.7448
A6: Web FE model | B6: run_FEmodel_webconf.py | F6: Lw (mm) | G6: 600 | H6: 2438.4
A7: Boundary FE model | B7: run_FEmodel_boundconf.py | F7: H (mm) | G7: 1200 | H7: 5276.8
A8: Calibration source | B8: PublicUse/MLmodel | F8: ρt (%) | G8: 0.1131 | H8: 1.7174
A9: Number of configurations | B9: 31 | F9: Lw/tw | G9: 5 | H9: 21.875
A10: Sampling design: | B10: Common crossed 20-point, two-dimensional Latin hypercube sampling (LHS). | F10: fylρl (MPa) | G10: 68.66 | H10: 1202.85
A11: LHS samples per configuration | B11: 20 | F11: fyvρv (MPa) | G11: 157.08 | H11: 1477.79
A12: Total analytical specimens | B12: 620 | F12: Acc (mm²) | G12: 0 | H12: 242736
A13: LHS seed | B13: 120
A14: Concrete strength range (MPa) | B14: 20-60
A15: ALR range (%) | B15: 5-45
A16: Web rho_l definition | B16: rho_l = n_face * A_bar / (s * t_w)
A17: Model-error lower factor | B17: 0.747
A18: Model-error upper factor | B18: 1.067
A19: Model-error bound scope | B19: Applied only to flexure-dominated analytical specimens; shear-susceptible specimens marked NA or left blank.
A20: Failure mode classification criteria | B20: Derived from V_CE/V_MCyE >= 1.15; engineering classification, not simulated physical shear failure
A21: Public repository naming note | B21: W-HL-3 is the standardized configuration identifier used in the manuscript and public database
A23: Delta_u_lower_bound_mm | B23: Lower model-error bound: Delta_u_abs_mm multiplied by the factor in Metadata!B16 (0.747). Unit: mm.
A24: Delta_u_upper_bound_mm | B24: Upper model-error bound: Delta_u_abs_mm multiplied by the factor in Metadata!B17 (1.067). Unit: mm.
A25: mu_lower_bound | B25: Lower model-error bound: mu_abs multiplied by the factor in Metadata!B16 (0.747). Dimensionless.
A26: mu_upper_bound | B26: Upper model-error bound: mu_abs multiplied by the factor in Metadata!B17 (1.067). Dimensionless.
A27: Bound interpretation | B27: Bounds apply only to flexure-dominated analytical specimens. NA or blank entries indicate that these bounds are not assigned. The multipliers represent the adopted model-error bounds, not positive/negative loading branches.
A28: ML calibration ranges | B28: Metadata!F5:H12 gives the eight input ranges from the implemented 110-Walls model: PublicUse/MLmodel/110-Walls/supportFiles/XtrainMin.txt and XtrainMax.txt.
A29: ML_range_status | B29: Within calibration ranges: all eight inputs lie within their inclusive limits. Outside calibration ranges: at least one input lies outside. These precomputed indicators describe the supplied analytical specimens and must be recomputed if inputs or calibration limits change.
A30: ML_out_of_range_inputs | B30: Semicolon-separated names of inputs outside their calibration limits. None means no input is outside. Missing input means the check cannot be completed.
A31: ML range interpretation | B31: This is a specimen-specific, univariate input-range check. Being within all ranges does not establish joint training-data coverage or guarantee prediction accuracy.
... A41: Recalculation scope | B41: The E formulas update ALR and rho_t exceedances. Changes to other ML inputs, calibration bounds, or the case set require repeating the full eight-input screening before interpreting E_max. Existing range-status labels are precomputed.

Sheet Common_LHS_20
A1: LHS_sample | B1: LHS_seed | C1: fc_MPa | D1: ALR
A2: 1 | B2: 120 | C2: 22.11414 | D2: 28.832066
A3: 2 | B3: 120 | C3: 39.289373 | D3: 11.435997
A4: 3 | B4: 120 | C4: 50.720967 | D4: 41.572102
A5: 4 | B5: 120 | C5: 40.065365 | D5: 25.230644
A6: 5 | B6: 120 | C6: 44.69165 | D6: 35.27886
A7: 6 | B7: 120 | C7: 33.0865 | D7: 19.795806
A8: 7 | B8: 120 | C8: 42.943728 | D8: 31.604416
A9: 8 | B9: 120 | C9: 29.155455 | D9: 7.3398505
A10: 9 | B10: 120 | C10: 59.748609 | D10: 37.783512
A11: 10 | B11: 120 | C11: 34.746338 | D11: 23.741461
A12: 11 | B12: 120 | C12: 24.502162 | D12: 33.048591
A13: 12 | B13: 120 | C13: 56.241154 | D13: 14.787645
... A21: 20 | B21: 120 | C21: 53.035991 | D21: 30.346543

Sheet Configuration_Definitions
A1: Configuration | B1: Configuration_family | C1: rho_bl | D1: rho_sh | E1: rho_l | F1: rho_t | G1: dbar_mm | H1: webspacing_mm | I1: dbar1_mm | J1: no_bars_bl
A2: Base model | B2: Reference | C2: 1.57 | D2: 1.5 | E2: 0.54 | F2: 0.25 | G2: 8 | H2: 125
A3: W-L | B3: Web | C3: 1.57 | D3: 1.5 | E3: 0.27 | F3: 0.18 | G3: 8 | H3: 250
A4: W-VL | B4: Web | C4: 1.57 | D4: 1.5 | E4: 0.2 | F4: 0.12 | G4: 6 | H4: 190
A5: W-M | B5: Web | C5: 1.57 | D5: 1.5 | E5: 0.4 | F5: 0.3 | G5: 8 | H5: 170
A6: W-H | B6: Web | C6: 1.57 | D6: 1.5 | E6: 0.78 | F6: 0.4 | G6: 10 | H6: 135
A7: W-VH | B7: Web | C7: 1.57 | D7: 1.5 | E7: 0.95 | F7: 0.55 | G7: 10 | H7: 110
A8: W-HL-1 | B8: Web | C8: 1.57 | D8: 1.5 | E8: 0.84 | F8: 0.1 | G8: 10 | H8: 125
A9: W-HL-2 | B9: Web | C9: 1.57 | D9: 1.5 | E9: 0.95 | F9: 0.15 | G9: 10 | H9: 110
A10: W-HL-3 | B10: Web | C10: 1.57 | D10: 1.5 | E10: 1.2 | F10: 0.2 | G10: 12 | H10: 125
A11: W-LH-1 | B11: Web | C11: 1.57 | D11: 1.5 | E11: 0.15 | F11: 0.4 | G11: 6 | H11: 250
A12: W-LH-2 | B12: Web | C12: 1.57 | D12: 1.5 | E12: 0.2 | F12: 0.5 | G12: 6 | H12: 190
A13: W-LH-3 | B13: Web | C13: 1.57 | D13: 1.5 | E13: 0.25 | F13: 0.6 | G13: 6 | H13: 150
... A20: W-Z-4 | B20: Web | C20: 1.57 | D20: 1.5 | E20: 1.2 | F20: 0.05 | G20: 12 | H20: 125
A21: B-L | B21: Boundary | C21: 1.09 | D21: 0.6 | E21: 0.54 | F21: 0.25 | I21: 10 | J21: 8
A22: B-M | B22: Boundary | C22: 1.57 | D22: 1 | E22: 0.54 | F22: 0.25 | I22: 12 | J22: 8
A23: B-IM | B23: Boundary | C23: 1.36 | D23: 1.25 | E23: 0.54 | F23: 0.25 | I23: 10 | J23: 10
A24: B-H | B24: Boundary | C24: 1.95 | D24: 1.8 | E24: 0.54 | F24: 0.25 | I24: 12 | J24: 10
A25: B-VH | B25: Boundary | C25: 2.13 | D25: 2.2 | E25: 0.54 | F25: 0.25 | I25: 14 | J25: 8
A26: U-1 | B26: Boundary | C26: 1.17 | D26: 0.8 | E26: 0.54 | F26: 0.25 | I26: 12 | J26: 6
A27: U-2 | B27: Boundary | C27: 0.82 | D27: 0.6 | E27: 0.54 | F27: 0.25 | I27: 10 | J27: 6
A28: U-3 | B28: Boundary | C28: 0.82 | D28: 0.45 | E28: 0.54 | F28: 0.25 | I28: 10 | J28: 6
A29: U-4 | B29: Boundary | C29: 0.54 | D29: 0.4 | E29: 0.54 | F29: 0.25 | I29: 10 | J29: 4
A30: OR-1 | B30: Boundary | C30: 2.35 | D30: 2.6 | E30: 0.54 | F30: 0.25 | I30: 12 | J30: 12
A31: OR-2 | B31: Boundary | C31: 2.8 | D31: 3 | E31: 0.54 | F31: 0.25 | I31: 16 | J31: 8
A32: OR-3 | B32: Boundary | C32: 3.5 | D32: 3.2 | E32: 0.54 | F32: 0.25 | I32: 18 | J32: 8
